<?xml version="1.0"?>

<robot xmlns:xacro="http://www.ros.org/wiki/xacro">


    <xacro:property name="arm_length" value="0.1" />
    <xacro:property name="arm_width" value="0.1" />
    <xacro:property name="arm_height" value="0.02" />
    <xacro:property name="arm_mass" value="0.5" />


    <xacro:property name="forearm_mass" value="0.3" />
    <xacro:property name="forearm_length" value="0.3" />
    <xacro:property name="forearm_radius" value="0.02" />


    <xacro:property name="hand_mass" value="0.3" />
    <xacro:property name="hand_length" value="0.3" />
    <xacro:property name="hand_radius" value="0.02" />


    <link name="base_footprint">
    </link>
    <link name="arm_base_link">
        <visual>
            <geometry>
                <box size="${arm_length} ${arm_width} ${arm_height}" />
            </geometry>
            <material name="orange" />
            <origin xyz="0 0 0" rpy="0 0 0" />
        </visual>
        <collision>
            <geometry>
                <box size="${arm_length} ${arm_width} ${arm_height}" />
            </geometry>
        </collision>
        <xacro:box_inertia m="${arm_mass}" l="${arm_length}" w="${arm_width}" h="${arm_height}"
            xyz="0 0 0" rpy="0 0 0" />
    </link>

    <link name="forearm_link">
        <visual>
            <geometry>
                <cylinder length="${forearm_length}" radius="${forearm_radius}" />
            </geometry>
            <material name="yellow" />
            <origin xyz="0 0 .15" rpy="0 0 0" />
        </visual>
        <collision>
            <geometry>
                <cylinder length="${forearm_length}" radius="${forearm_radius}" />
            </geometry>
        </collision>
        <xacro:cylinder_inertia m="${forearm_mass}" r="${forearm_radius}" h="${forearm_length}"
            xyz="0 0 0" rpy="0 0 0" />
    </link>

    <link name="hand_link">
        <visual>
            <geometry>
                <cylinder length="${hand_length}" radius="${hand_radius}" />
                <material name="orange" />
                <origin xyz="0 0 0}" rpy="0 0 0" />
            </geometry>
        </visual>
        <collision>
            <geometry>
                <cylinder length="${hand_length}" radius="${hand_radius}" />
            </geometry>
        </collision>
        <xacro:cylinder_inertia m="${hand_mass}" r="${hand_radius}" h="${hand_length}"
            xyz="0 0 0" rpy="0 0 0" />

    </link>
    <joint name="hand_forearm_joint" type="revolute">
        <parent link="forearm_link" />
        <child link="hand_link" />
        <axis xyz="0 1 0" />
        <limit effort="100.0" lower="0.0" upper="${pi / 2}" velocity="100.0" />
        <dynamics friction="0.05" damping="0.1" />
        <!-- <origin xyz="0 0 ${forearm_length}" rpy="0 0 0" /> -->

        <origin xyz="0 0 0" rpy="0 0 0" />
    </joint>


    <joint name="base_joint" type="fixed">
        <parent link="base_footprint" />
        <child link="arm_base_link" />
        <origin xyz="0 0 0" rpy="0 0 0" />
    </joint>

    <joint name="forearm_arm_joint" type="revolute">
        <parent link="arm_base_link" />
        <child link="forearm_link" />
        <axis xyz="0 1 0" />
        <limit effort="100.0" lower="0.0" upper="${pi / 2}" velocity="100.0" />
        <dynamics friction="0.05" damping="0.1" />
        <!-- <origin xyz="0 0 .017" rpy="0 0 0" /> -->

        <origin xyz="0 0 .017" rpy="0 0 0" />
    </joint>



</robot>